<?xml version="1.0" encoding="utf-8"?>

<robot name="robot">
  <link name="base_footprint"></link>
  <joint name="base_joint" type="fixed">
    <parent link="base_footprint" />
    <child link="base_link" />
    <origin xyz="0 0 0.0" rpy="0 0 0" />
  </joint>
  <link name="base_link">
    <visual>
      <origin xyz="0 0 0" rpy="0 0 0" />
      <geometry>
        <mesh filename="package://airosa_description/meshes/base_link.STL" />
      </geometry>
      <material name="base_link-material">
        <color rgba="0.5 1 0.2 1" />
      </material>
    </visual>
    <collision>
      <origin xyz="0 0 0" rpy="0 0 0" />
      <geometry>
        <box size="0.08 0.08 0.01" />
      </geometry>
    </collision>
    <inertial>
      <origin xyz="0 0 0" rpy="0 0 0" />
      <mass value="0.1" />
      <inertia ixx="0.0" ixy="0" ixz="0" iyy="0.0" iyz="0" izz="0.0" />
    </inertial>
  </link>
  <joint name="FRcoxa" type="revolute">
    <parent link="base_link" />
    <child link="coxa1" />
    <origin xyz="0.04 0.04 0" rpy="0 0 -0.7853981633974485" />
    <axis xyz="0 0 1"/>
    <limit effort="0.0" lower="-1" upper="1" velocity="0.5"/>  </joint>
  <link name="coxa1">
    <visual>
      <origin xyz="0.0 0.0 0.0035" rpy="0 0 0.7853981633974485" />
      <geometry>
        <mesh filename="package://airosa_description/meshes/frcoxa_link.STL" />
      </geometry>
      <material name="coxa1-material">
        <color rgba="0.0 0.3 0.4 1" />
      </material>
    </visual>
    <collision>
      <origin xyz="0 0.0135 0" rpy="0 0 0" />
      <geometry>
        <box size="0.01 0.027 0.01" />
      </geometry>
    </collision>
    <inertial>
      <origin xyz="0 0.0135 0" rpy="0 0 0" />
      <mass value="0.1" />
      <inertia ixx="0.0" ixy="0" ixz="0" iyy="0.0" iyz="0" izz="0.0" />
    </inertial>
  </link>
  <joint name="FRfemur" type="revolute">
    <parent link="coxa1" />
    <child link="femur1" />
    <origin xyz="0 0.0265 0.02675" rpy="3.141592653589793 1.5707963267948966 3.141592653589793" />
    <axis xyz="0 0 1"/>
    <limit effort="0.0" lower="-1" upper="1" velocity="0.5"/>  </joint>
  <link name="femur1">
    <visual>
      <origin xyz="0 0 0" rpy="0 0 0" />
      <geometry>
        <mesh filename="package://airosa_description/meshes/flfemur_link.STL" />
      </geometry>
      <material name="femur1-material">
        <color rgba="0.4 0.0 0.0 1" />
      </material>
    </visual>
    <collision>
      <origin xyz="0 0.025 0" rpy="0 0 0" />
      <geometry>
        <box size="0.01 0.05 0.01" />
      </geometry>
    </collision>
    <inertial>
      <origin xyz="0 0.025 0" rpy="0 0 0" />
      <mass value="0.1" />
      <inertia ixx="0.0" ixy="0" ixz="0" iyy="0.0" iyz="0" izz="0.0" />
    </inertial>
  </link>
  <joint name="FRtibia" type="revolute">
    <parent link="femur1" />
    <child link="tibia1" />
    <origin xyz="-0.0001 0.05 0" rpy="0 0 0" />
    <axis xyz="0 0 -1"/>
    <limit effort="0.0" lower="-1" upper="1" velocity="0.5"/>  </joint>
  <link name="tibia1">
    <visual>
      <origin xyz="0 0 0" rpy="0 0 -1.5707963267948966" />
      <geometry>
        <mesh filename="package://airosa_description/meshes/fltibia_link.STL" />
      </geometry>
      <material name="tibia1-material">
        <color rgba="0.2 0.4 0.0 1" />
      </material>
    </visual>
    <collision>
      <origin xyz="0 0.03 0" rpy="0 0 0" />
      <geometry>
        <box size="0.01 0.06 0.01" />
      </geometry>
    </collision>
    <inertial>
      <origin xyz="0 0.03 0" rpy="0 0 0" />
      <mass value="0.1" />
      <inertia ixx="0.0" ixy="0" ixz="0" iyy="0.0" iyz="0" izz="0.0" />
    </inertial>
  </link>
  <joint name="FLcoxa" type="revolute">
    <parent link="base_link" />
    <child link="coxa2" />
    <origin xyz="-0.04 0.04 0" rpy="0 0 0.7853981633974484" />
    <axis xyz="0 0 1"/>
    <limit effort="0.0" lower="-1" upper="1" velocity="0.5"/>  </joint>
  <link name="coxa2">
    <visual>
      <origin xyz="0 0 0.0035" rpy="0 0 0.7853981633974484" />
      <geometry>
        <mesh filename="package://airosa_description/meshes/frcoxa_link.STL" />
      </geometry>
      <material name="coxa2-material">
        <color rgba="0.0 0.3 0.4 1" />
      </material>
    </visual>
    <collision>
      <origin xyz="0 0.0135 0" rpy="0 0 0" />
      <geometry>
        <box size="0.01 0.027 0.01" />
      </geometry>
    </collision>
    <inertial>
      <origin xyz="0 0.0135 0" rpy="0 0 0" />
      <mass value="0.1" />
      <inertia ixx="0.0" ixy="0" ixz="0" iyy="0.0" iyz="0" izz="0.0" />
    </inertial>
  </link>
  <joint name="FLfemur" type="revolute">
    <parent link="coxa2" />
    <child link="femur2" />
    <origin xyz="0 0.0265 0.02675" rpy="3.141592653589793 1.5707963267948966 3.141592653589793" />
    <axis xyz="0 0 1"/>
    <limit effort="0.0" lower="-1" upper="1" velocity="0.5"/>  </joint>
  <link name="femur2">
    <visual>
      <origin xyz="0 0 0" rpy="0 0 0" />
      <geometry>
        <mesh filename="package://airosa_description/meshes/flfemur_link.STL" />
      </geometry>
      <material name="femur2-material">
        <color rgba="0.4 0.0 0.0 1" />
      </material>
    </visual>
    <collision>
      <origin xyz="0 0.025 0" rpy="0 0 0" />
      <geometry>
        <box size="0.01 0.05 0.01" />
      </geometry>
    </collision>
    <inertial>
      <origin xyz="0 0.025 0" rpy="0 0 0" />
      <mass value="0.1" />
      <inertia ixx="0.0" ixy="0" ixz="0" iyy="0.0" iyz="0" izz="0.0" />
    </inertial>
  </link>
  <joint name="FLtibia" type="revolute">
    <parent link="femur2" />
    <child link="tibia2" />
    <origin xyz="-0.0001 0.05 0" rpy="0 0 0" />
    <axis xyz="0 0 -1"/>
    <limit effort="0.0" lower="-1" upper="1" velocity="0.5"/>  </joint>
  <link name="tibia2">
    <visual>
      <origin xyz="0 0 0" rpy="0 0 -1.5707963267948966" />
      <geometry>
        <mesh filename="package://airosa_description/meshes/fltibia_link.STL" />
      </geometry>
      <material name="tibia2-material">
        <color rgba="0.2 0.4 0.0 1" />
      </material>
    </visual>
    <collision>
      <origin xyz="0 0.03 0" rpy="0 0 0" />
      <geometry>
        <box size="0.01 0.06 0.01" />
      </geometry>
    </collision>
    <inertial>
      <origin xyz="0 0.03 0" rpy="0 0 0" />
      <mass value="0.1" />
      <inertia ixx="0.0" ixy="0" ixz="0" iyy="0.0" iyz="0" izz="0.0" />
    </inertial>
  </link>
  <joint name="BRcoxa" type="revolute">
    <parent link="base_link" />
    <child link="coxa3" />
    <origin xyz="0.04 -0.04 0" rpy="0 0 -2.356194490192345" />
    <axis xyz="0 0 1"/>
    <limit effort="0.0" lower="-1" upper="1" velocity="0.5"/>  </joint>
  <link name="coxa3">
    <visual>
      <origin xyz="0 0 0.0035" rpy="0 0 0.7853981633974485" />
      <geometry>
        <mesh filename="package://airosa_description/meshes/frcoxa_link.STL" />
      </geometry>
      <material name="coxa3-material">
        <color rgba="0.0 0.3 0.4 1" />
      </material>
    </visual>
    <collision>
      <origin xyz="0 0.0135 0" rpy="0 0 0" />
      <geometry>
        <box size="0.01 0.027 0.01" />
      </geometry>
    </collision>
    <inertial>
      <origin xyz="0 0.0135 0" rpy="0 0 0" />
      <mass value="0.1" />
      <inertia ixx="0.0" ixy="0" ixz="0" iyy="0.0" iyz="0" izz="0.0" />
    </inertial>
  </link>
  <joint name="BRfemur" type="revolute">
    <parent link="coxa3" />
    <child link="femur3" />
    <origin xyz="0 0.0265 0.02675" rpy="3.141592653589793 1.5707963267948966 3.141592653589793" />
    <axis xyz="0 0 1"/>
    <limit effort="0.0" lower="-1" upper="1" velocity="0.5"/>  </joint>
  <link name="femur3">
    <visual>
      <origin xyz="0 0 0" rpy="0 0 0" />
      <geometry>
        <mesh filename="package://airosa_description/meshes/flfemur_link.STL" />
      </geometry>
      <material name="femur3-material">
        <color rgba="0.4 0.0 0.0 1" />
      </material>
    </visual>
    <collision>
      <origin xyz="0 0.025 0" rpy="0 0 0" />
      <geometry>
        <box size="0.01 0.05 0.01" />
      </geometry>
    </collision>
    <inertial>
      <origin xyz="0 0.025 0" rpy="0 0 0" />
      <mass value="0.1" />
      <inertia ixx="0.0" ixy="0" ixz="0" iyy="0.0" iyz="0" izz="0.0" />
    </inertial>
  </link>
  <joint name="BRtibia" type="revolute">
    <parent link="femur3" />
    <child link="tibia3" />
    <origin xyz="-0.0001 0.05 0" rpy="0 0 0" />
    <axis xyz="0 0 -1"/>
    <limit effort="0.0" lower="-1" upper="1" velocity="0.5"/>  </joint>
  <link name="tibia3">
    <visual>
      <origin xyz="0 0 0" rpy="0 0 -1.5707963267948966" />
      <geometry>
        <mesh filename="package://airosa_description/meshes/fltibia_link.STL" />
      </geometry>
      <material name="tibia3-material">
        <color rgba="0.2 0.4 0.0 1" />
      </material>
    </visual>
    <collision>
      <origin xyz="0 0.03 0" rpy="0 0 0" />
      <geometry>
        <box size="0.01 0.06 0.01" />
      </geometry>
    </collision>
    <inertial>
      <origin xyz="0 0.03 0" rpy="0 0 0" />
      <mass value="0.1" />
      <inertia ixx="0.0" ixy="0" ixz="0" iyy="0.0" iyz="0" izz="0.0" />
    </inertial>
  </link>
  <joint name="BLcoxa" type="revolute">
    <parent link="base_link" />
    <child link="coxa4" />
    <origin xyz="-0.04 -0.04 0" rpy="0 0 2.356194490192345" />
    <axis xyz="0 0 1"/>
    <limit effort="0.0" lower="-1" upper="1" velocity="0.5"/>  </joint>
  <link name="coxa4">
    <visual>
      <origin xyz="0 0 0.0035" rpy="0 0 0.7853981633974485" />
      <geometry>
        <mesh filename="package://airosa_description/meshes/frcoxa_link.STL" />
      </geometry>
      <material name="coxa4-material">
        <color rgba="0.0 0.3 0.4 1" />
      </material>
    </visual>
    <collision>
      <origin xyz="0 0.0135 0" rpy="0 0 0" />
      <geometry>
        <box size="0.01 0.027 0.01" />
      </geometry>
    </collision>
    <inertial>
      <origin xyz="0 0.0135 0" rpy="0 0 0" />
      <mass value="0.1" />
      <inertia ixx="0.0" ixy="0" ixz="0" iyy="0.0" iyz="0" izz="0.0" />
    </inertial>
  </link>
  <joint name="BLfemur" type="revolute">
    <parent link="coxa4" />
    <child link="femur4" />
    <origin xyz="0 0.0265 0.02675" rpy="3.141592653589793 1.5707963267948966 3.141592653589793" />
    <axis xyz="0 0 1"/>
    <limit effort="0.0" lower="-1" upper="1" velocity="0.5"/>  </joint>
  <link name="femur4">
    <visual>
      <origin xyz="0 0 0" rpy="0 0 0" />
      <geometry>
        <mesh filename="package://airosa_description/meshes/flfemur_link.STL" />
      </geometry>
      <material name="femur4-material">
        <color rgba="0.4 0.0 0.0 1" />
      </material>
    </visual>
    <collision>
      <origin xyz="0 0.025 0" rpy="0 0 0" />
      <geometry>
        <box size="0.01 0.05 0.01" />
      </geometry>
    </collision>
    <inertial>
      <origin xyz="0 0.025 0" rpy="0 0 0" />
      <mass value="0.1" />
      <inertia ixx="0.0" ixy="0" ixz="0" iyy="0.0" iyz="0" izz="0.0" />
    </inertial>
  </link>
  <joint name="BLtibia" type="revolute">
    <parent link="femur4" />
    <child link="tibia4" />
    <origin xyz="-0.0001 0.05 0" rpy="0 0 0" />
    <axis xyz="0 0 -1"/>
    <limit effort="0.0" lower="-1" upper="1" velocity="0.5"/>  </joint>
  <link name="tibia4">
    <visual>
      <origin xyz="0 0 0" rpy="0 0 -1.5707963267948966" />
      <geometry>
        <mesh filename="package://airosa_description/meshes/fltibia_link.STL" />
      </geometry>
      <material name="tibia4-material">
        <color rgba="0.2 0.4 0.0 1" />
      </material>
    </visual>
    <collision>
      <origin xyz="0 0.03 0" rpy="0 0 0" />
      <geometry>
        <box size="0.01 0.06 0.01" />
      </geometry>
    </collision>
    <inertial>
      <origin xyz="0 0.03 0" rpy="0 0 0" />
      <mass value="0.1" />
      <inertia ixx="0.0" ixy="0" ixz="0" iyy="0.0" iyz="0" izz="0.0" />
    </inertial>
  </link>
  <joint name="laser_joint" type="fixed">
    <parent link="base_link" />
    <child link="lidar" />
    <origin xyz="0 0 0.02" rpy="0 0 0" />
    <axis xyz="0 0 1"/>
  </joint>
  <link name="lidar">
    <visual>
      <origin xyz="0 0 0" rpy="0 0 0" />
      <geometry>
        <cylinder radius="0.03" length="0.03" />
      </geometry>
      <material name="lidar-material">
        <color rgba="0 0 0 1" />
      </material>
    </visual>
    <collision>
      <origin xyz="0 0 0" rpy="0 0 0" />
      <geometry>
        <cylinder radius="0.03" length="0.03" />
      </geometry>
    </collision>
    <inertial>
      <origin xyz="0 0 0" rpy="0 0 0" />
      <mass value="0.1" />
      <inertia ixx="0.0" ixy="0" ixz="0" iyy="0.0" iyz="0" izz="0.0" />
    </inertial>
  </link>
  <joint name="lds_joint" type="fixed">
    <parent link="base_link" />
    <child link="lds" />
    <origin xyz="0 0 0" rpy="0 0 0" />
    <axis xyz="0 0 0"/>
  </joint>
  <link name="lds">
    <visual>
      <origin xyz="0 0 0" rpy="0 0 0" />
      <geometry>
        <mesh filename="package://airosa_description/meshes/lidar_base.STL"/>
      </geometry>
      <material name="lds-material">
        <color rgba="0 0 0 1" />
      </material>
    </visual>
    <collision>
      <origin xyz="0 0 0.1592" rpy="0 0 0" />
      <geometry>
        <cylinder radius="0.03" length="0.03" />
      </geometry>
    </collision>
    <inertial>
      <origin xyz="0 0 0" rpy="0 0 0" />
      <mass value="0.1" />
      <inertia ixx="0.0" ixy="0" ixz="0" iyy="0.0" iyz="0" izz="0.0" />
    </inertial>
  </link>
</robot>
